Workbook

Sheet SchB
A1: SCHEDULE- 'B'
A2: =cover!A24 -> Carrying out survey and investigation for KT weir on {{River}} River of near {{Village}} village Tal. {{Taluka}} Dist. {{District}}
A3: Quantity | B3: Description of Item | D3: Unit | E3: Rate | G3: Amount
E4: In Figures | F4: In Words
A5: =#REF! -> #REF! | B5: Item No 1 | C5: =[1]abst!D6 -> Clearing and removing grass,bushes & shrubs etc & stacking the stuff up to lead 15 m & lift 1.5 m | D5: =[1]abst!F6 -> Sqm | E5: =[2]abst!E6 -> 4.95 | F5: Rupees Four and Paise Ninety Five Only. | G5: =#REF! -> #REF!
A6: =#REF! -> #REF! | B6: Item No 2 | C6: =[1]abst!D7 -> Carrying Bench Mark from G.T.S. Bench Mark location to starting point with Auto level including closing the survey etc. complete. | D6: =[1]abst!F7 -> Km | E6: =[2]abst!E7 -> 2083.15 | F6: Rupees Two Thousand Eighty Three and Paise Fifteen Only. | G6: =#REF! -> #REF!
A7: =#REF! -> #REF! | B7: Item No 3 | C7: =[1]abst!D8 -> Contour survey including taking levels @ 10 m x 10 m blocks by using Total station Instrument, including Transportation Labour & Technical Person etc. complete. | D7: =[1]abst!F8 -> Hect | E7: =[2]abst!E8 -> 1188.75 | F7: Rupees One Thousand One Hundred Eighty Eight and Paise Seventy Five only | G7: =#REF! -> #REF!
A8: =#REF! -> #REF! | B8: Item No 4 | C8: =[1]abst!D9 -> Detailed Survey for River including necessary chain compassing, levelling taking L-Section & taking Cross Sections and other details by using Total station Instrument, including Transportation Labour & Technical Person etc. complete. | D8: =[1]abst!F9 -> Km | E8: =[2]abst!E9 -> 11110 | F8: Rupees Eleven Thousand One Hundred Ten only | G8: =#REF! -> #REF!
A9: =#REF! -> #REF! | B9: Item No 5 | C9: =[1]abst!D10 -> Providing and fixing chainage ,stone, appexes, bench mark in cement concrete 1 : 4 : 8 block of size 45 x 45 x 60 cm. including , excavation, conveyance etc. complete. | D9: =[1]abst!F10 -> Rmt | E9: =[2]abst!E10 -> 554.4 | F9: Rupees Five Hundred Fifty Four and Paise Forty only | G9: =#REF! -> #REF!
C10: Total | G10: =SUM(G5:G9) -> #REF!
F11: Say Rs. | G11: =ROUND(G10,0) -> #REF!
A13: Rupees Fourteen Lakhs Seventy Eight Thousand Five Hundred Sixty Two only

Sheet cover
A13: Government of Maharashtra
A15: Water Resources Department
A17: Konkan Region, Mumbai
A19: {{Circle}}
A21: {{Division}}
A24: Carrying out survey and investigation for KT weir on {{River}} River of near {{Village}} village Tal. {{Taluka}} Dist. {{District}}
E30: ESTIMATE
A37: {{Sub_Division}}

Sheet face sheet
A1: ESTIMATE
A5: DIVISION | C5: {{Division}}
A7: Sanctioned Estimate No. | C7: Vide | D7: for
A9: Capital Head | C9: State
A11: Main Head | C11: 2702 Survey & Investigation
A13: Sub Head | C13: Survey & Investigation
A15: Other Head | C15: Survey & Investigation
A18: Service Head
A20: Divisional Head
A21: Estimate Prepared in the Office of the Executive Engineer, {{Division}} For the Probable expenses to be incurred for Carrying out survey and investigation for KT weir on {{River}} of near {{Village}} village Tal. {{Taluka}} Dist. {{District}}
A24: Estimated cost Rs. | H24: ='Recapitulation Sheet'!C20 -> #VALUE!
A26: Administratively approved vide No. ----------------------------------- Dated
A27: Technically Sanctioned vide No. ----------------------------------- Dated
A30: Estimate Prepared By Shri
A32: Estimate Checked By Shri
A34: General Description

Sheet Recapitulation Sheet
A1: ='[3]Cover page'!A27:C27 -> Name of Work :- | B1: =cover!A24 -> Carrying out survey and investigation for KT weir on {{River}} River of near {{Village}} village Tal. {{Taluka}} Dist. {{District}}
B3: Recapitulation Sheet
A5: Sr. No. | B5: Name of Sub-Estimate | C5: Amount (Rs.)
A8: 1 | B8: =abst!B1:F1 -> Carrying out survey and investigation for KT weir on {{River}} River of near {{Village}} village Tal. {{Taluka}} Dist. {{District}} | C8: =abst!F18 -> #VALUE!
B12: Total Amount (Rs.) | C12: =SUM(C8:C10) -> #VALUE!
B14: Add 18% GST | C14: =C12*0.18 -> #VALUE!
B16: Add labour insurance 1% | C16: =C12*0.01 -> #VALUE!
B18: Gross Total Amount (Rs.) | C18: =SUM(C12:C16) -> #VALUE!
B20: Say (Rs.) | C20: =ROUND(C18,-1) -> #VALUE!
A23: Prepared by
B28: Sub Divisional Engineer | C28: Executive Engineer
A29: Junior Engineer | B29: {{SDE_1}} | C29: {{EE_1}}
B30: {{SDE_2}} | C30: {{EE_2}}

Sheet abst
A1: Name of work- | B1: =cover!A24 -> Carrying out survey and investigation for KT weir on {{River}} River of near {{Village}} village Tal. {{Taluka}} Dist. {{District}}
B2: A B S T R A C T
A3: Item No | B3: Quantity | C3: Item | D3: Rate | E3: Unit | F3: Amount
A4: 1 | B4: ='Measurement '!G12 -> #VALUE! | C4: Cleaning grass and removal of rubbish upto a distance of 50 meters outside the periphery of the area as directed. | D4: ='R.A1'!E9 -> 4.85 | E4: Sqm | F4: =D4*B4 -> #VALUE!
A5: 2 | B5: ='Measurement '!G20 -> 0 | C5: Double levelling using Auto level to connect Geodetic Trignometrical survey, benchmark and establishing permanent benchmark at Dam site at place along the canal alignment, submergence and in command area etc. complete, as directed.(Excluding cost of B.M. structure) | D5: ='R.A1'!E27 -> 1216.4 | E5: Km | F5: =D5*B5 -> 0 | I5: 1.1 | J5: pg 13
A6: 3 | B6: ='Measurement '!G29 -> #VALUE! | C6: Block contour survey of 10m x 10m grid (Not less than 121 raw data points distributed uniformly over a Hectare) for irrigation projects using digital state of art Total Station / DGPS, including transfer of entire data to computer system in different georeferential layer / themes using features of standard plotting Softwares compatible with canal irrigation system design Software packages including contour plotting at specified interval and scale. The test print of the drawing shall be approved by Engineer-in-charge and the same shall be delivered in a CD format as well as hard copy in six numbers. | D6: ='R.A1'!E43 -> 420.65 | E6: Ha | F6: =D6*B6 -> #VALUE!
A7: 4 | B7: ='Measurement '!G37 -> #VALUE! | C7: Block contour survey of 10m x 10m grid, using Differential Global Position System (DGPS) instrument including labour, transportation, using sounding by boat in river water in wet condition and transfer of entire data to computer system in different georeferential layers/ themes using features of standard plotting software computable with design software package including contour plotting at required interval and at a scale and following deliverables etc. all complete as directed. | D7: ='R.A1'!E111 -> 9134.3 | E7: ='Measurement '!H37 -> Ha | F7: =D7*B7 -> #VALUE!
A8: 5 | B8: ='Measurement '!G44 -> #VALUE! | C8: Carrying out line survey with digital state of art Total Station for fixing FRL/ HFL including C/s survey with levels at 20 m interval /survey for 'L' section of alternative Dam site OR 'L' section of river 1 Km u/s OR 1 Km D/s of alternative Dam site etc complete including station, including transfer of entire data to computer system in different georeferential layer /the mesusing features of standard plotting Softwares compatible with canal irrigation system design Softwares packages including contour plotting at specified interval and scale. The test print of the drawing shall be approved by Engineer -in- charge and the same shall be delivered in a CD format as well as hard copy in six numbers including one print on tracing paper as directed. | D8: ='R.A1'!E128 -> 859.45 | E8: Km | F8: =D8*B8 -> #VALUE!
A9: 6 | B9: ='Measurement '!G50 -> 2 | C9: Providing permanent bench mark dressed stone of basalt, granite or gneiss of size 30CmX30CmX45Cm at least 15Cm below the ground and embedding it to a depth of 30Cm in grade M-15 in situ concrete of size 90CmX90CmX60Cm deep over 1M deep foundation concrete of grade M-10 including excavation, concrete, providing and fixing dressed stone and backfilling the pit up to ground level with sand etc complete. with all lifts as directed. | D9: ='R.A1'!E142 -> 6565.45 | E9: ='Measurement '!H50 -> no | F9: =D9*B9 -> 13130.9
A10: 7 | C10: Taking trial bore for detailed investigation with NX diamond drill double tube in all sorts of soil like soft murum, hard murum and boulders including all materials such as casing pipes, accessories, grease, steel boolsam and other such materials and or as required including conveying such materials and machinery to site of works, preserving the loose samples in glass/plastic jar and core samples serially numbered at site of work and conveying the same to the head quarter of concerned office as directed and submission of detailed bore log sheet complete.(As directed by the Engineer in charge)
A11: a | B11: ='Measurement '!G59 -> #VALUE! | C11: Overburden (Soil of all sort, soft murum, hard murum, boulder and soft rock) | D11: ='R.A1'!E157 -> 2342.1 | E11: Rmt | F11: =D11*B11 -> #VALUE!
A12: b | B12: ='Measurement '!G66 -> #VALUE! | C12: Hard rock | D12: ='R.A1'!E164 -> 4340.1 | E12: Rmt | F12: =D12*B12 -> #VALUE!
A13: 8 | B13: ='Measurement '!G71 -> #VALUE! | C13: Providing core box of MS of size size 1.25mx0.35mx0.15m for preserving core sample with all fixtures and fastening handles including locking arrangement etc. complete. | D13: ='R.A1'!E178 -> 2808.2 | E13: No. | F13: =D13*B13 -> #VALUE!
A14: 9 | B14: ='Measurement '!G76 -> 1 | C14: Providing and maintaining temparory platform for erecting boring machine in river bed to the depth of standing water 2 m and above and of size 3.50 x 4.00 M by using 20 Nos. of M.S. empty barrels in M.S. frame made of M.S. angle size 50 x 50 x 5 mm with fabrication and over it in jungle wood planks platform of size 3.50 x 4.00 x 0.03 M size including supplying of nylon rope 24 mm dia. for anchoring platform include passage platform and engaging a labour etc. complete. 2 m and above. | D14: ='R.A1'!E194 -> 23991 | E14: No. | F14: =D14*B14 -> 23991
A15: 10 | B15: ='Measurement '!G81 -> #VALUE! | C15: Shifting boring plant with all its components and reinstalling the same at the directed place including all its charges etc. complete. | D15: ='R.A1'!E208 -> 9973.7 | E15: No. | F15: =D15*B15 -> #VALUE! | J15: Engineer In charge including back filling trial
A16: 11 | B16: ='Measurement '!G87 -> 1 | C16: Providing detailed geological reports of proposed site by maintaining geotechnical investigation of structure stratification collecting soil, rock and ground water samples for laboratory tests to arrive the foundation design parameters . Rock properties such as type of rock, jointing fractures, etc. complete with suggestion about the site foundation and remedies. | D16: ='R.A1'!E225 -> 42592 | E16: No. | F16: =D16*B16 -> 42592
D17: Total | E17: = | F17: =SUM(F4:F16) -> #VALUE!
A18: ='Recapitulation Sheet'!A23 -> Prepared by | E18: Say | F18: =ROUND(F17,0) -> #VALUE!
C22: ='Recapitulation Sheet'!B28 -> Sub Divisional Engineer | D22: ='Recapitulation Sheet'!C28 -> Executive Engineer
A23: ='Recapitulation Sheet'!A29 -> Junior Engineer | C23: ='Recapitulation Sheet'!B29 -> {{SDE_1}} | D23: ='Recapitulation Sheet'!C29 -> {{EE_1}}
C24: ='Recapitulation Sheet'!B30 -> {{SDE_2}} | D24: ='Recapitulation Sheet'!C30 -> {{EE_2}}

Sheet Measurement 
A1: =cover!A24 -> Carrying out survey and investigation for KT weir on {{River}} River of near {{Village}} village Tal. {{Taluka}} Dist. {{District}}
A3: Measurement Sheet
A5: ='R.A1'!A4 -> Item No.1 :- | B5: =abst!C4 -> Cleaning grass and removal of rubbish upto a distance of 50 meters outside the periphery of the area as directed.
B7: Location | D7: L (m) | E7: B (m) | F7: Nos | G7: Qty
B8: Both side of river | D8: {{L}} | E8: 10 | F8: 2 | G8: =D8*E8*F8 -> #VALUE! | H8: sqm | K8: =2109*10000 -> 21090000
G10: =SUM(G8:G9) -> #VALUE! | H10: =H8 -> sqm
B12: Considering {{I_P}}% Intensity = | E12: =VALUE(G10)&" * "&VALUE(K12)&" =" -> #VALUE! | G12: =G10*K12 -> #VALUE! | H12: sqm | K12: {{I_F}}
A14: ='R.A1'!A22 -> Item No.2 :- | B14: =abst!C5 -> Double levelling using Auto level to connect Geodetic Trignometrical survey, benchmark and establishing permanent benchmark at Dam site at place along the canal alignment, submergence and in command area etc. complete, as directed.(Excluding cost of B.M. structure)
B16: Location | D16: L (m) | F16: Nos | G16: Qty in Km
B17: Carrying BM | D17: {{BM_L}} | G17: =D17 -> {{BM_L}} | H17: m
F19: TOTAL = | G19: =SUM(G17:G18) -> 0 | H19: m | L19: 40000 | M19: =1.5*L19 -> 60000
F20: Say | G20: =G19/1000 -> 0 | H20: Km
A22: ='R.A1'!A38 -> Item No.3 :- | B22: =abst!C6 -> Block contour survey of 10m x 10m grid (Not less than 121 raw data points distributed uniformly over a Hectare) for irrigation projects using digital state of art Total Station / DGPS, including transfer of entire data to computer system in different georeferential layer / themes using features of standard plotting Softwares compatible with canal irrigation system design Software packages including contour plotting at specified interval and scale. The test print of the drawing shall be approved by Engineer-in-charge and the same shall be delivered in a CD format as well as hard copy in six numbers.
B23: Location | D23: L (m) | E23: B (m) | G23: Qty
B24: Submergence area | D24: =D8 -> {{L}} | E24: {{B}} | F24: 1/10000 | G24: =D24*E24/10000 -> #VALUE! | H24: Ha
B25: Considering {{Dry_Area}}% area is in dry as there is continuous water.
B26: Hence Submergence area in dry= | D26: {{Dry_Area}}% | E26: X | F26: =G24 -> #VALUE! | G26: =D26*F26 -> #VALUE! | H26: Ha
B28: Increase 25% of submergence for HFL (of total area) | G28: =G24*0.25 -> #VALUE! | H28: =H24 -> Ha
F29: Total= | G29: =G26+G28 -> #VALUE! | H29: =H28 -> Ha
A31: ='R.A1'!A52 -> Item No.4 :- | B31: ='R.A1'!B52 -> Block contour survey of 10m x 10m grid, using Differential Global Position System (DGPS) instrument including labour, transportation, using sounding by boat in river water in wet condition and transfer of entire data to computer system in different georeferential layers/ themes using features of standard plotting software computable with design software package including contour plotting at required interval and at a scale and following deliverables etc. all complete as directed.
B32: Location | D32: L (m) | E32: B (m) | G32: Qty
B33: Submergence area | D33: =D8 -> {{L}} | E33: =E24 -> {{B}} | F33: 1/10000 | G33: =D33*E33/10000 -> #VALUE! | H33: Ha
B34: Considering {{Wet_Area}}% area is in Wet as there is continuous water
B35: Hence Submergence area in Wet= | D35: {{Wet_Area}}% | E35: X | F35: =G33 -> #VALUE! | G35: =D35*F35 -> #VALUE! | H35: Ha
F37: Total= | G37: =G35 -> #VALUE! | H37: =H35 -> Ha
A39: ='R.A1'!A123 -> Item No.5 :- | B39: =abst!C8 -> Carrying out line survey with digital state of art Total Station for fixing FRL/ HFL including C/s survey with levels at 20 m interval /survey for 'L' section of alternative Dam site OR 'L' section of river 1 Km u/s OR 1 Km D/s of alternative Dam site etc complete including station, including transfer of entire data to computer system in different georeferential layer /the mesusing features of standard plotting Softwares compatible with canal irrigation system design Softwares packages including contour plotting at specified interval and scale. The test print of the drawing shall be approved by Engineer -in- charge and the same shall be delivered in a CD format as well as hard copy in six numbers including one print on tracing paper as directed.
B40: Location | D40: L (m) | E40: B (m) | F40: Nos | G40: Qty
B41: Weir line with alternate alignment | D41: =E33 -> {{B}} | F41: 3 | G41: =D41*F41 -> #VALUE! | H41: m
B42: Along river length | D42: =D8 -> {{L}} | F42: 1 | G42: =D42*F42 -> #VALUE! | H42: m
G43: =SUM(G41:G42) -> #VALUE! | H43: m
E44: Total | F44: = | G44: =G43/1000 -> #VALUE! | H44: km
A46: ='R.A1'!A137 -> Item No.6 :- | B46: =abst!C9 -> Providing permanent bench mark dressed stone of basalt, granite or gneiss of size 30CmX30CmX45Cm at least 15Cm below the ground and embedding it to a depth of 30Cm in grade M-15 in situ concrete of size 90CmX90CmX60Cm deep over 1M deep foundation concrete of grade M-10 including excavation, concrete, providing and fixing dressed stone and backfilling the pit up to ground level with sand etc complete. with all lifts as directed.
D47: Nos | E47: Length (m) | F47: Quantity | G47: Qty
B48: B.M. structure | D48: 2 | F48: =D48 -> 2 | G48: =F48 -> 2 | H48: no
B49: 1 at Weir site, 1 at Submergence
F50: Say | G50: =G48 -> 2 | H50: =H48 -> no
A53: ='R.A1'!A151 -> Item No.7 :- | B53: =abst!C10 -> Taking trial bore for detailed investigation with NX diamond drill double tube in all sorts of soil like soft murum, hard murum and boulders including all materials such as casing pipes, accessories, grease, steel boolsam and other such materials and or as required including conveying such materials and machinery to site of works, preserving the loose samples in glass/plastic jar and core samples serially numbered at site of work and conveying the same to the head quarter of concerned office as directed and submission of detailed bore log sheet complete.(As directed by the Engineer in charge)
B54: A) For Overburdon ({{B_R}} bores in river and {{B_B}} on banks)
D55: Alignments | E55: No of bores | F55: Depth | G55: Qty in m
D56: 1 | E56: {{B_R}} | F56: {{O_R_D}} | G56: =F56*E56*D56 -> #VALUE!
...

Sheet R.A1
A1: =cover!A24 -> Carrying out survey and investigation for KT weir on {{River}} River of near {{Village}} village Tal. {{Taluka}} Dist. {{District}}
A3: Rate Analysis No 1
A4: Item No.1 :- | B4: =abst!C4 -> Cleaning grass and removal of rubbish upto a distance of 50 meters outside the periphery of the area as directed.
B5: Rate as per CSR 2023-24, Pg 64, Item MR4 | H5: 4.35 | I5: /sqm
B6: Add 10% Tribal Charges | H6: =0.1*H5 -> 0.435 | I6: /sqm
B7: Add 1 % for Labour Welfare Cess | H7: =0.01*H5 -> 0.0435 | I7: /sqm
B8: Grand Total | H8: =SUM(H5:H7) -> 4.8285 | I8: /sqm
D9: Say Rs | E9: =ROUND((H8/0.05),0)*0.05 -> 4.85 | F9: per Sqm
A10: Prepared by
D16: Sub Divisional Engineer | G16: Executive Engineer
D17: {{SDE_1}} | G17: {{EE_1}}
A18: Junior Engineer | D18: {{SDE_2}} | G18: {{EE_2}}
A22: Item No.2 :- | B22: =abst!C5 -> Double levelling using Auto level to connect Geodetic Trignometrical survey, benchmark and establishing permanent benchmark at Dam site at place along the canal alignment, submergence and in command area etc. complete, as directed.(Excluding cost of B.M. structure)
B23: Rate as per CSR 2023-24, Pg 46, Item SI1 | H23: 1095.85 | I23: /Km
B24: Add 10% Tribal Charges | H24: =0.1*H23 -> 109.585 | I24: /Km
B25: Add 1 % for Labour Welfare Cess | H25: =0.01*H23 -> 10.9585 | I25: /Km
B26: Grand Total | H26: =SUM(H23:H25) -> 1216.3935 | I26: /Km
D27: Say Rs | E27: =ROUND((H26/0.05),0)*0.05 -> 1216.4 | F27: per Km
A28: Prepared by
D34: Sub Divisional Engineer | G34: Executive Engineer
D35: {{SDE_1}} | G35: {{EE_1}}
A36: Junior Engineer | D36: {{SDE_2}} | G36: {{EE_2}}
A38: Item No.3 :- | B38: =abst!C6 -> Block contour survey of 10m x 10m grid (Not less than 121 raw data points distributed uniformly over a Hectare) for irrigation projects using digital state of art Total Station / DGPS, including transfer of entire data to computer system in different georeferential layer / themes using features of standard plotting Softwares compatible with canal irrigation system design Software packages including contour plotting at specified interval and scale. The test print of the drawing shall be approved by Engineer-in-charge and the same shall be delivered in a CD format as well as hard copy in six numbers.
B39: Rate as per CSR 2023-24, Pg 46, Item SI2 | H39: 378.97 | I39: /ha
B40: Add 10% Tribal Charges | H40: =0.1*H39 -> 37.897 | I40: =I39 -> /ha
B41: Add 1 % for Labour Welfare Cess | H41: =0.01*H39 -> 3.7897 | I41: =I40 -> /ha
B42: Grand Total | H42: =SUM(H39:H41) -> 420.6567 | I42: =I41 -> /ha
D43: Say Rs | E43: =ROUND((H42/0.05),0)*0.05 -> 420.65 | F43: per Ha
A44: Prepared by
D48: Sub Divisional Engineer | G48: Executive Engineer
D49: {{SDE_1}} | G49: {{EE_1}}
A50: Junior Engineer | D50: {{SDE_2}} | G50: {{EE_2}}
A52: Item No.4 :- | B52: =abst!C7 -> Block contour survey of 10m x 10m grid, using Differential Global Position System (DGPS) instrument including labour, transportation, using sounding by boat in river water in wet condition and transfer of entire data to computer system in different georeferential layers/ themes using features of standard plotting software computable with design software package including contour plotting at required interval and at a scale and following deliverables etc. all complete as directed.
B53: Assumptions:
B54: As per field experience, 1 survey party including 1 Civil Engr., 1 surveyor & 5 labours record carryout approximately 12.0 Km. survey/day
B55: For Area = 100 X 100m = 1 Ha.
B56: No. of C/s at every 10m = (100/10)+1=11 Nos.
B57: 11 Km. line survey = 1 Ha.
B58: Linear progress per day with level at every 10m is = 12.0Km
B59: Therefore 12.0 Km. line survey Thus daily output = 1.32 Ha. = 1/11 x 12.0 = 1.32 Ha.
...
