Workbook

Sheet RA
A1: Start/repeat | B1: Pump Houses | C1: Sr. No. | D1: Description | E1: PH1
A2: repeat | C2: A) | D2: SUBSTATION | E2: Unit | F2: Quantity (in Nos.) | G2: Cost per unit (in Rs.) | H2: 15 % erection,testing,commissioning charges | I2: Transport charges 3 % | J2: Contractor Profit 5 % | K2: Labour Cess 1 % | L2: Total Cost (in Rs.) (1+2+3+4+5) | M2: Add 10 for Hilly | N2: Sum (6+7) | O2: Add 1% for Labour Wellfare | P2: Total Amount (8+9)
G3: 1 | H3: 2 | I3: 3 | J3: 4 | K3: 5 | L3: 6 | M3: 7 | N3: 8 | O3: 9 | P3: 10
H9: 0.15 | I9: 0.03 | J9: 0.05 | K9: 0.01
B10: PH1, PH2, PH3, PH4 | C10: 2 | D10: 220 kV EQUIPMENT :
C11: 2.1 | D11: SF6 Circuit Breaker, 3-Ph gang operated complete with operating mechanism & support structure | E11: Nos. | F11: 6 | G11: =1528333 -> 1528333 | H11: =G11*15% -> 229249.95 | I11: =G11*3% -> 45849.99 | J11: =G11*5% -> 76416.65 | K11: =G11*1% -> 15283.33 | L11: =SUM(G11:K11) -> 1895132.9 | M11: =L11*10% -> 189513.29 | N11: =M11+L11 -> 2084646.2 | O11: =N11*1% -> 20846.462 | P11: =N11+O11 -> 2105492.7 | Q11: WRD Hydro Electrical CSR 2022_23 pg 19/51
C12: 2.2 | D12: 3-Ph gang operated double break centre post rotating outdoor type motor operated disconnector (Isolator) with solid core post insulator.
C13: a) | D13: Without earth switch | E13: Nos. | F13: 10 | G13: 188123 | H13: =G13*15% -> 28218.45 | I13: =G13*3% -> 5643.69 | J13: =G13*5% -> 9406.15 | K13: =G13*1% -> 1881.23 | L13: =SUM(G13:K13) -> 233272.52 | M13: =L13*10% -> 23327.252 | N13: =M13+L13 -> 256599.77 | O13: =N13*1% -> 2565.9977 | P13: =N13+O13 -> 259165.77 | Q13: WRD Hydro Electrical CSR 2022_23 pg21/51
C14: b) | D14: With one earth switch( manual ) | E14: Nos. | F14: 7 | G14: 236843 | H14: =G14*15% -> 35526.45 | I14: =G14*3% -> 7105.29 | J14: =G14*5% -> 11842.15 | K14: =G14*1% -> 2368.43 | L14: =SUM(G14:K14) -> 293685.32 | M14: =L14*10% -> 29368.532 | N14: =M14+L14 -> 323053.85 | O14: =N14*1% -> 3230.5385 | P14: =N14+O14 -> 326284.39 | Q14: WRD Hydro Electrical CSR 2022_23 pg21/51
C15: c) | D15: With two earth switch ( manual ) | E15: Nos. | F15: 9 | G15: =G14 -> 236843 | H15: =G15*15% -> 35526.45 | I15: =G15*3% -> 7105.29 | J15: =G15*5% -> 11842.15 | K15: =G15*1% -> 2368.43 | L15: =SUM(G15:K15) -> 293685.32 | M15: =L15*10% -> 29368.532 | N15: =M15+L15 -> 323053.85 | O15: =N15*1% -> 3230.5385 | P15: =N15+O15 -> 326284.39 | Q15: WRD Hydro Electrical CSR 2022_23 pg21/51
C16: 2.3 | D16: lightning arrestor. | E16: Nos. | F16: 15 | G16: =G15 -> 236843 | H16: =G16*15% -> 35526.45 | I16: =G16*3% -> 7105.29 | J16: =G16*5% -> 11842.15 | K16: =G16*1% -> 2368.43 | L16: =SUM(G16:K16) -> 293685.32 | M16: =L16*10% -> 29368.532 | N16: =M16+L16 -> 323053.85 | O16: =N16*1% -> 3230.5385 | P16: =N16+O16 -> 326284.39 | Q16: WRD Hydro Electrical CSR 2022_23 pg20/51
C17: 2.4 | D17: Out door single phase current transformers for:
C18: a) | D18: Transformer feeder | E18: Nos. | F18: 9 | G18: 72600 | H18: =G18*15% -> 10890 | I18: =G18*3% -> 2178 | J18: =G18*5% -> 3630 | K18: =G18*1% -> 726 | L18: =SUM(G18:K18) -> 90024 | M18: =L18*10% -> 9002.4 | N18: =M18+L18 -> 99026.4 | O18: =N18*1% -> 990.264 | P18: =N18+O18 -> 100016.66 | Q18: WRD Hydro Electrical CSR 2022_23 pg21/51
C19: b) | D19: Line feeder | E19: Nos. | F19: 12 | G19: 78100 | H19: =G19*15% -> 11715 | I19: =G19*3% -> 2343 | J19: =G19*5% -> 3905 | K19: =G19*1% -> 781 | L19: =SUM(G19:K19) -> 96844 | M19: =L19*10% -> 9684.4 | N19: =M19+L19 -> 106528.4 | O19: =N19*1% -> 1065.284 | P19: =N19+O19 -> 107593.68 | Q19: WRD Hydro Electrical CSR 2022_23 pg21/51
C20: 2.5 | D20: Capacitive voltage transformer | E20: Nos. | F20: 12 | G20: =53883 -> 53883 | H20: =G20*15% -> 8082.45 | I20: =G20*3% -> 1616.49 | J20: =G20*5% -> 2694.15 | K20: =G20*1% -> 538.83 | L20: =SUM(G20:K20) -> 66814.92 | M20: =L20*10% -> 6681.492 | N20: =M20+L20 -> 73496.412 | O20: =N20*1% -> 734.96412 | P20: =N20+O20 -> 74231.376 | Q20: WRD Hydro Electrical CSR 2022_23 pg22/51
C21: 2.6 | D21: Potential transformer | E21: Nos. | F21: 6 | G21: =53883 -> 53883 | H21: =G21*15% -> 8082.45 | I21: =G21*3% -> 1616.49 | J21: =G21*5% -> 2694.15 | K21: =G21*1% -> 538.83 | L21: =SUM(G21:K21) -> 66814.92 | M21: =L21*10% -> 6681.492 | N21: =M21+L21 -> 73496.412 | O21: =N21*1% -> 734.96412 | P21: =N21+O21 -> 74231.376 | Q21: WRD Hydro Electrical CSR 2022_23 pg22/51
C22: 2.7 | D22: Solid core post insulator(Bus ) | E22: Nos. | F22: 6 | G22: =22372.54+1882.43 -> 24254.97 | L22: =F22*G22 -> 145529.82 | O22: Nos. | Q22: Maha Transco 2025 pg 35/121
C23: 3 | D23: Substation Bay Hardware, 220kV side
C24: 3.1 | D24: Single tension insulator asembly with all hardwares accessories ACSR MOOSE conductor | E24: Set | F24: 12 | G24: =1228*1.2 -> 1473.6 | L24: =F24*G24 -> 17683.2 | O24: Set | Q24: Maha Transco 2025 page 49/121
C25: 3.2 | D25: 120 KN Disc insulator | E25: Nos. | F25: 12 | G25: =1104*1.2 -> 1324.8 | L25: =F25*G25 -> 15897.6 | O25: Nos. | Q25: Maha Transco 2025 page 49/121
C26: 4 | D26: Clamp and terminal connectors suitable for Moose ACSR conductors on 220 kV side | E26: LS | F26: 1 | G26: 150000 | L26: =G26*F26 -> 150000 | O26: LS
D27: Conductor & Accessories
D28: Shield Wire & Accessories
C29: 5 | D29: Power & control cable
C30: 5.1 | D30: Power cable
C31: a) | D31: 11kV XLPE insulated armoured cable of the following sizes:
C32: i | D32: 3.5 Core x 240 sqmm for station transformer (2 runs) | E32: Mtr. | F32: =3*50*2 -> 300 | G32: 3000 | L32: =F32*G32 -> 900000 | O32: Mtr. | Q32: Cable manf. List price - Polycab or eqvivalent
C33: ii | D33: Termination with double compression gland and Al lugs in ACDB for 3 1/2 core x 240 sq, mm cable | E33: Set | F33: 6 | G33: 10000 | L33: =F33*G33 -> 60000 | O33: Set
C34: b) | D34: 1.1 KV PVC insulated, armoured cable of the following size including cable support (For AC supply & yard lighting)
C35: i | D35: 4 core x 10 sqmm Al. Conductor cable | E35: Mtr. | F35: 250 | G35: 193 | L35: =F35*G35 -> 48250 | O35: Mtr. | Q35: MJP-Mech-CSR-2023-24 page 55/168
C36: ii | D36: 4 core x 16 sqmm Al. Conductor cable | E36: Mtr. | F36: 200 | G36: 213 | L36: =F36*G36 -> 42600 | O36: Mtr. | Q36: MJP-Mech-CSR-2023-24 page 55/168
C37: iii | D37: 3.5 core x 70 sqmm Al. Conductor cable for oil filtration set | E37: Mtr. | F37: 50 | G37: 494 | L37: =F37*G37 -> 24700 | M37: =G37*10% -> 49.4 | N37: =M37+G37 -> 543.4 | O37: =N37*1% -> 5.434 | P37: =O37+N37 -> 548.834 | Q37: PWD-Electrical-CSR-2022-23-All-Consolidated-1 page 137/321
C38: c) | D38: 31/2 core x 50 sqmm Al conductor cable ( GI Strip armoured) for ACDB to Battery charger | E38: Mtr. | F38: 20 | G38: 381 | L38: =F38*G38 -> 7620 | M38: =G38*10% -> 38.1 | N38: =M38+G38 -> 419.1 | O38: =N38*1% -> 4.191 | P38: =O38+N38 -> 423.291 | Q38: PWD-Electrical-CSR-2022-23-All-Consolidated-1 page 137/321
C39: d) | D39: 31/2 core x 50 sqmm Al conductor cable ( GI Strip armoured) for ACDB to BMK | E39: Mtr. | F39: 300 | G39: 381 | L39: =F39*G39 -> 114300 | M39: =G39*10% -> 38.1 | N39: =M39+G39 -> 419.1 | O39: =N39*1% -> 4.191 | P39: =O39+N39 -> 423.291 | Q39: PWD-Electrical-CSR-2022-23-All-Consolidated-1 page 137/321
C40: e) | D40: 2 core x 50 sqmm copper conductor cable (For DC) Battery charger to Battery | E40: Mtr. | F40: 25 | G40: 1050 | L40: =F40*G40 -> 26250 | O40: Mtr. | Q40: Cable manf. List price - Polycab or eqvivalent
C41: f) | D41: Cable Glands & lugs for item 5.1 b,c,d & e | E41: Lot | F41: 1 | G41: 30000 | L41: =F41*G41 -> 30000 | O41: Lot
C42: 5.2 | D42: Copper Control Cable
C43: a) | D43: 1100 V grade, PVC insulated, armoured, stranded control cables with termination including lugs, glands, ferrules and all other accessories | E43: Lot | F43: 1 | G43: 2000000 | L43: =G43*F43 -> 2000000 | O43: Lot
C44: 6 | D44: EARTHING AND LIGHTNING PROTECTION | E44: Lot | F44: 1 | G44: 3773127.8 | L44: =G44 -> 3773127.8 | O44: Lot
C45: a) | D45: Main Earth mat and Aux Earth mat shall be done by 40mm dia MS rod
...

Sheet TL DC MOOSE
A2: Start
A3: repeat | B3: 220kV TRANSMISSION LINE with MOOSE CONDUCTOR - DC | L3: Rate Reference
C5: 1 | D5: Key Inputs
C6: 1.1 | D6: Total Length considered | E6: 50 | F6: Kms
C7: 1.2 | D7: Span | E7: 300 | F7: mtr
C8: 1.3 | D8: Total towers | E8: =E6*1000/E7 -> 166.66667 | F8: Nos
C9: 1.4 | D9: Say, | E9: =CEILING(E8,1) -> 167 | F9: Nos
C11: 2 | D11: 220kV Transmission Towers
C12: 2.1 | D12: Tower Type | E12: Bifurcation | F12: Nos | G12: Weight (MT) | H12: Price per MT | I12: Amount
C13: 2.2 | D13: A type | E13: 0.8 | F13: =CEILING((E13*$E$9),1) -> 134 | G13: 6 | H13: 85000 | I13: =H13*G13*F13 -> 68340000
C14: 2.3 | D14: C type | E14: 0.2 | F14: =CEILING((E14*$E$9),1) -> 34 | G14: 7.5 | H14: 85000 | I14: =H14*G14*F14 -> 21675000
C15: 2.4 | D15: D type 2 nos (Start + End) | F15: 2 | G15: 8.5 | H15: 85000 | I15: =H15*G15*F15 -> 1445000
C16: 2.5 | D16: Tower Supply Cost of towers (In INR) | I16: =SUM(I13:I15) -> 91460000
C17: 2.6 | D17: Civil work associated with Towers | G17: @ | H17: 0.2 | I17: =I16*H17 -> 18292000
C18: 2.6 | D18: Tower Supply Cost of towers including CIVIL works (In INR) | I18: =I16+I17 -> 109752000
C20: 3 | D20: ACSR Conductor - MOOSE
C21: 3.1 | D21: Weight of Conductor per mtr - | E21: 2 | F21: kg
C22: 3.2 | D22: Conductor price kg/per mtr (INR) | E22: =250*1.05*1.02 -> 267.75
C23: 3.3 | D23: Total cost per mtr (INR) | E23: 386.9
C24: 3.4 | D24: Cost per km (INR) for SC per conductor | E24: =E23*1000 -> 386900
C25: 3.4 | D25: Cost per km (INR) for SC line | E25: =E24*3 -> 1160700
C26: 3.5 | D26: Cost per KM - DC Circuit (INR) per conductor | E26: =E25*2 -> 2321400
C27: 3.7 | D27: Considering sag @ | E27: =E26*F27 -> 69642 | F27: 0.03
C28: 3.8 | D28: Cost per KM - DC Circuit (INR) | E28: =E26+E27 -> 2391042
C29: 3.9 | D29: For said km distance (INR) | E29: =E28*E6 -> 119552100
C30: 3.9 | D30: Conductor Accessories, EW, FO & other equipment Cost @ | E30: =E29*F30 -> 23910420 | F30: 0.2
C31: 4 | D31: Total Cost for Conductor - per km for DC (INR) | E31: =E30+E29 -> 143462520
C33: 6 | D33: Total Supply Cost For Tower + Conductor | E33: =E31+I18 -> 253214520
C34: 7 | D34: Installation Cost @ | E34: =E33*F34 -> 37982178 | F34: 0.15
C36: 8 | D36: Total SITC cost for the said KM line | E36: =E34+E33 -> 291196698 | F36: =E6 -> 50 | G36: kms
C38: 9 | D38: Total SITC cost of DC MOOSE line per KM (in INR) | E38: =E36/F36 -> 5823934
C40: 10 | D40: Design & Survey works per km @ | E40: =E38*G40 -> 291196.7 | G40: 0.05
A43: End | B43: Table 2

Sheet SUMMARY
A3: Start | B3: Length of TL DC Moose conductor (in kms.) | C3: ='TL DC MOOSE'!E6 -> 50
B4: Total Cost of TL DC Moose conductor per km | C4: Length of TL DC Moose conductor with 25% tolerance (in kms)
B10: {=SUM('TL DC MOOSE'!E38:F38+'TL DC MOOSE'!E40:F40)} -> 6115130.7 | C10: =1.25*C3 -> 62.5
A14: End | B14: Table 3
A19: Start | B19: Option 1
B20: PH 1 | C20: ='Link 1'!H130 -> 2.1890524e+09
B21: PH 2 | C21: ='Link 1'!L130 -> 2.2852254e+09
B22: PH 3 | C22: ='Link 1'!P130 -> 2.3319187e+09
B23: PH 4 | C23: ='Link 1'!T130 -> 2.2877393e+09
B25: TL | C25: =B10*C10 -> 3.8219567e+08
B27: Total | C27: =SUM(C20:C26) -> 9.4761314e+09
A29: End | B29: Table 4

Sheet Link 1
A2: Start/repeat | B2: Pump Houses | C2: Sr. No. | D2: Description | E2: Nikhop | I2: Shindipada | M2: Savaroli | Q2: Chonde
C3: A) | D3: SUBSTATION | E3: Unit | F3: Quantity (in Nos.) | G3: Cost per unit (in Rs.) | H3: Total Cost (in Rs.) | I3: Unit | J3: Quantity (in Nos.) | K3: Cost per unit (in Rs.) | L3: Total Cost (in Rs.) | M3: Unit | N3: Quantity (in Nos.) | O3: Cost per unit (in Rs.) | P3: Total Cost (in Rs.) | Q3: Unit | R3: Quantity (in Nos.) | S3: Cost per unit (in Rs.) | T3: Total Cost (in Rs.)
C4: 1 | D4: TRANSFORMER
C5: a) | D5: 220/11 kV, 3-Ph, YNyn0, Cu. winding, ONAN Transformer with OLTC (+ 5 % - 15 % in step of 1.25 %) and RTCC panel
B6: PH1 | C6: i) | D6: 25 MVA | E6: Nos. | F6: 3 | G6: 47862565 | H6: 1.4358769e+08 | U6: Maha Transco 2025 page(Supply - 34of 121, ETC - 54of 121)
B7: PH2 | C7: ii) | D7: 60 MVA | I7: Nos. | J7: 3 | K7: 82578120 | L7: 2.4773436e+08 | U7: Maha Transco 2025 page(Supply - 34of 121, ETC - 54of 121) 15.% additional on 50MVA price
B8: PH3 | C8: iii) | D8: 75 MVA | M8: Nos. | N8: 3 | O8: 96939532 | P8: 2.908186e+08 | U8: Maha Transco 2025 page(Supply - 34of 121, ETC - 54of 121) 35% additional on 50MVA price
B9: PH4 | C9: iv) | D9: 100 MVA | Q9: Nos. | R9: 3 | S9: 78962840 | T9: 2.3688852e+08 | U9: Maha Transco 2025 page(Supply - 34of 121, ETC - 54of 121)
B11: PH1, PH2, PH3, PH4 | C11: 2 | D11: 220 kV EQUIPMENT :
C12: 2.1 | D12: SF6 Circuit Breaker, 3-Ph gang operated complete with operating mechanism & support structure | E12: Nos. | F12: 6 | G12: 2105492.7 | H12: 12632956 | I12: Nos. | J12: 6 | K12: 1681166 | L12: 10086996 | M12: Nos. | N12: 6 | O12: 1681166 | P12: 10086996 | Q12: Nos. | R12: 6 | S12: 1681166 | T12: 10086996 | U12: WRD Hydro Electrical CSR 2022_23 pg 19/51
C13: 2.2 | D13: 3-Ph gang operated double break centre post rotating outdoor type motor operated disconnector (Isolator) with solid core post insulator.
C14: a) | D14: Without earth switch | E14: Nos. | F14: 10 | G14: 259165.77 | H14: 2591657.7 | I14: Nos. | J14: 10 | K14: 188123 | L14: 1881230 | M14: Nos. | N14: 10 | O14: 188123 | P14: 1881230 | Q14: Nos. | R14: 10 | S14: 188123 | T14: 1881230 | U14: WRD Hydro Electrical CSR 2022_23 pg21/51
C15: b) | D15: With one earth switch( manual ) | E15: Nos. | F15: 7 | G15: 326284.39 | H15: 2283990.7 | I15: Nos. | J15: 7 | K15: 236843 | L15: 1657901 | M15: Nos. | N15: 7 | O15: 236843 | P15: 1657901 | Q15: Nos. | R15: 7 | S15: 236843 | T15: 1657901 | U15: WRD Hydro Electrical CSR 2022_23 pg21/51
C16: c) | D16: With two earth switch ( manual ) | E16: Nos. | F16: 9 | G16: 326284.39 | H16: 2936559.5 | I16: Nos. | J16: 9 | K16: 355265 | L16: 3197385 | M16: Nos. | N16: 9 | O16: 355265 | P16: 3197385 | Q16: Nos. | R16: 9 | S16: 355265 | T16: 3197385 | U16: WRD Hydro Electrical CSR 2022_23 pg21/51 - (Consideration - 1.5*Single Earth Switch)
C17: 2.3 | D17: lightning arrestor. | E17: Nos. | F17: 15 | G17: 326284.39 | H17: 4894265.9 | I17: Nos. | J17: 15 | K17: 92000 | L17: 1380000 | M17: Nos. | N17: 15 | O17: 92000 | P17: 1380000 | Q17: Nos. | R17: 15 | S17: 92000 | T17: 1380000 | U17: WRD Hydro Electrical CSR 2022_23 pg20/51
C18: 2.4 | D18: Out door single phase current transformers for:
C19: a) | D19: Transformer feeder | E19: Nos. | F19: 9 | G19: 100016.66 | H19: 900149.98 | I19: Nos. | J19: 9 | K19: 72600 | L19: 653400 | M19: Nos. | N19: 9 | O19: 72600 | P19: 653400 | Q19: Nos. | R19: 9 | S19: 72600 | T19: 653400 | U19: WRD Hydro Electrical CSR 2022_23 pg21/51
C20: b) | D20: Line feeder | E20: Nos. | F20: 12 | G20: 107593.68 | H20: 1291124.2 | I20: Nos. | J20: 12 | K20: 78100 | L20: 937200 | M20: Nos. | N20: 12 | O20: 78100 | P20: 937200 | Q20: Nos. | R20: 12 | S20: 78100 | T20: 937200 | U20: WRD Hydro Electrical CSR 2022_23 pg21/51
C21: 2.5 | D21: Capacitive voltage transformer | E21: Nos. | F21: 12 | G21: 74231.376 | H21: 890776.51 | I21: Nos. | J21: 12 | K21: 61965 | L21: 743580 | M21: Nos. | N21: 12 | O21: 61965 | P21: 743580 | Q21: Nos. | R21: 12 | S21: 61965 | T21: 743580 | U21: WRD Hydro Electrical CSR 2022_23 pg22/51
C22: 2.6 | D22: Potential transformer | E22: Nos. | F22: 6 | G22: 74231.376 | H22: 445388.26 | I22: Nos. | J22: 6 | K22: 61965 | L22: 371790 | M22: Nos. | N22: 6 | O22: 61965 | P22: 371790 | Q22: Nos. | R22: 6 | S22: 61965 | T22: 371790 | U22: WRD Hydro Electrical CSR 2022_23 pg22/51
C23: 2.7 | D23: Solid core post insulator(Bus ) | E23: Nos. | F23: 6 | G23: 24254.97 | H23: 145529.82 | I23: Nos. | J23: 6 | K23: 24254.97 | L23: 145529.82 | M23: Nos. | N23: 6 | O23: 24254.97 | P23: 145529.82 | Q23: Nos. | R23: 6 | S23: 24254.97 | T23: 145529.82 | U23: Maha Transco 2025 page(Supply - 34, ETC - 54)
C24: 3 | D24: Substation Bay Hardware, 220kV side
C25: 3.1 | D25: Single tension insulator asembly with all hardwares accessories ACSR MOOSE conductor | E25: Set | F25: 12 | G25: 1867.9786 | H25: 22415.743 | I25: Set | J25: 12 | K25: 1867.9786 | L25: 22415.743 | M25: Set | N25: 12 | O25: 1867.9786 | P25: 22415.743 | Q25: Set | R25: 12 | S25: 1867.9786 | T25: 22415.743 | U25: Maha Transco 2025 page 49/121 (Supply) +500-Inst
C26: 3.2 | D26: 90 KN Disc insulator | E26: Nos. | F26: 12 | G26: 1746.186 | H26: 20954.232 | I26: Nos. | J26: 12 | K26: 1746.186 | L26: 20954.232 | M26: Nos. | N26: 12 | O26: 1746.186 | P26: 20954.232 | Q26: Nos. | R26: 12 | S26: 1746.186 | T26: 20954.232 | U26: Maha Transco 2025 page 49/121 (Supply) +500-Inst
C27: 4 | D27: Clamp and terminal connectors suitable for Moose ACSR conductors on 220 kV side | E27: LS | F27: 1 | G27: 150000 | H27: 150000 | I27: LS | J27: 1 | K27: 150000 | L27: 150000 | M27: LS | N27: 1 | O27: 150000 | P27: 150000 | Q27: LS | R27: 1 | S27: 150000 | T27: 150000
D28: Conductor & Accessories
D29: Shield Wire & Accessories
C30: 5 | D30: Power & control cable
C31: 5.1 | D31: Power cable
C32: a) | D32: 11kV XLPE insulated armoured cable of the following sizes:
C33: i | D33: 3.5 Core x 240 sqmm for station transformer (2 runs) | E33: Mtr. | F33: 300 | G33: 3000 | H33: 900000 | I33: Mtr. | J33: 300 | K33: 3000 | L33: 900000 | M33: Mtr. | N33: 300 | O33: 3000 | P33: 900000 | Q33: Mtr. | R33: 300 | S33: 3000 | T33: 900000 | U33: Cable manf. List price - Polycab or eqvivalent
C34: ii | D34: Termination with double compression gland and Al lugs in ACDB for 3 1/2 core x 240 sq, mm cable | E34: Set | F34: 6 | G34: 10000 | H34: 60000 | I34: Set | J34: 6 | K34: 10000 | L34: 60000 | M34: Set | N34: 6 | O34: 10000 | P34: 60000 | Q34: Set | R34: 6 | S34: 10000 | T34: 60000
C35: b) | D35: 1.1 KV PVC insulated & sheathed, GI steel armoured cable of the following size including cable support (For AC supply & yard lighting)
C36: i | D36: 4 core x 10 sqmm Al. Conductor cable | E36: Mtr. | F36: 250 | G36: 172 | H36: 43000 | I36: Mtr. | J36: 250 | K36: 172 | L36: 43000 | M36: Mtr. | N36: 250 | O36: 172 | P36: 43000 | Q36: Mtr. | R36: 250 | S36: 172 | T36: 43000 | U36: MJP-Mech-CSR-2023-24 page 55/168
C37: ii | D37: 4 core x 16 sqmm Al. Conductor cable | E37: Mtr. | F37: 200 | G37: 192 | H37: 38400 | I37: Mtr. | J37: 200 | K37: 192 | L37: 38400 | M37: Mtr. | N37: 200 | O37: 192 | P37: 38400 | Q37: Mtr. | R37: 200 | S37: 192 | T37: 38400 | U37: MJP-Mech-CSR-2023-24 page 55/168
C38: iii | D38: 3.5 core x 70 sqmm Al. Conductor cable for oil filtration set | E38: Mtr. | F38: 50 | G38: 548.834 | H38: 27441.7 | I38: Mtr. | J38: 50 | K38: 494 | L38: 24700 | M38: Mtr. | N38: 50 | O38: 494 | P38: 24700 | Q38: Mtr. | R38: 50 | S38: 494 | T38: 24700 | U38: PWD-Electrical-CSR-2022-23-All-Consolidated-1 page 137/321
C39: c) | D39: 31/2 core x 50 sqmm Al conductor cable ( GI Strip armoured) for ACDB to Battery charger | E39: Mtr. | F39: 20 | G39: 423.291 | H39: 8465.82 | I39: Mtr. | J39: 20 | K39: 381 | L39: 7620 | M39: Mtr. | N39: 20 | O39: 381 | P39: 7620 | Q39: Mtr. | R39: 20 | S39: 381 | T39: 7620 | U39: PWD-Electrical-CSR-2022-23-All-Consolidated-1 page 137/321
C40: d) | D40: 31/2 core x 50 sqmm Al conductor cable ( GI Strip armoured) for ACDB to BMK | E40: Mtr. | F40: 300 | G40: 423.291 | H40: 126987.3 | I40: Mtr. | J40: 300 | K40: 381 | L40: 114300 | M40: Mtr. | N40: 300 | O40: 381 | P40: 114300 | Q40: Mtr. | R40: 300 | S40: 381 | T40: 114300 | U40: PWD-Electrical-CSR-2022-23-All-Consolidated-1 page 137/321
C41: e) | D41: 2 core x 50 sqmm copper conductor cable (For DC) Battery charger to Battery | E41: Mtr. | F41: 25 | G41: 650.52 | H41: 16263 | I41: Mtr. | J41: 25 | K41: 650.52 | L41: 16263 | M41: Mtr. | N41: 25 | O41: 650.52 | P41: 16263 | Q41: Mtr. | R41: 25 | S41: 650.52 | T41: 16263 | U41: Cable manf. List price - Polycab or eqvivalent
C42: f) | D42: Cable Glands & lugs for item 5.1 b,c,d & e | E42: Lot | F42: 1 | G42: 30000 | H42: 30000 | I42: Lot | J42: 1 | K42: 30000 | L42: 30000 | M42: Lot | N42: 1 | O42: 30000 | P42: 30000 | Q42: Lot | R42: 1 | S42: 30000 | T42: 30000
...
