Workbook
Name \0: #REF!
Name \0: #REF!
Name \a: #REF!
Name \a: #REF!
Name \b: #REF!
Name \C: [1]CALC!#REF!
Name \C: [2]CALC!#REF!
Name \F: '[3]ABS %'!#REF!
Name \F: '[4]ABS %'!#REF!
Name \o: #REF!
Name \p: #REF!
Name \S: '[3]ABS %'!#REF!
Name \S: '[4]ABS %'!#REF!
Name _ALK210: #REF!
Name _car1: [5]Sheet2!#REF!
Name _CCM100: [1]CALC!#REF!
Name _CCM100: [2]CALC!#REF!
Name _CCM150: [1]CALC!#REF!
Name _CCM150: [2]CALC!#REF!
Name _CCM200: [1]CALC!#REF!
Name _CCM200: [2]CALC!#REF!
Name _CCM75: [1]CALC!#REF!
Name _CCM75: [2]CALC!#REF!
Name _MTH1: #REF!
Name _MTH2: #REF!
Name _MTV1: #REF!
Name _MTV2: #REF!
Name _TH1: #REF!
Name _TH2: #REF!
Name _TV1: #REF!
Name _TV2: #REF!
Name _YR1: #REF!
Name a: #REF!
Name A2O4: #REF!
Name a34AI144: #REF!
Name aa: #REF!
Name AAAA: [8]DATA!#REF!
Name ab: [8]DATA!#REF!
Name ABCD: #REF!
Name ABS: '[3]ABS %'!#REF!
Name ABS: '[4]ABS %'!#REF!
Name ABVBELOW: [9]DATA!$M$5
Name arp: #REF!
Name Arun: [10]Est_Data!#REF!
Name asd_2: [10]Est_Data!#REF!
Name ASL: [11]DATA!#REF!
Name ASPHALTJT: [1]CALC!#REF!
Name ASPHALTJT: [2]CALC!#REF!
Name ASR: [11]DATA!#REF!
Name Average_annual_rainfall: #REF!
Name b: #REF!
Name BACKFILL: [1]CALC!#REF!
Name BACKFILL: [2]CALC!#REF!
Name BACKFILLHM: [1]CALC!#REF!
Name BACKFILLHM: [2]CALC!#REF!
Name BANKING: [1]CALC!#REF!
Name BANKING: [2]CALC!#REF!
Name bbkb: #REF!
Name beldar: [5]Sheet2!#REF!
Name bhat: [12]Data!#REF!

Sheet Cover
A13: Government of Maharashtra
A15: Water Resources Department
A17: Konkan Region, Mumbai
A19: {{Circle}}, {{District}}
B21: {{EE_1}}, | G21: {{EE_2}}
A23: Name of Work -
A24: Preparing Emergency Action Plan of {{Scheme}} {{Type}} and Survey for Computation and defining the Red Line and Blue Line for {{River_Name}} Tal. {{Taluka}}, Dist. {{District}} | N24: Preparing Emergency Action Plan of Jambhe M.I. Project and Survey for Computation and defining the Red Line and Blue Line for Local Nala at Jambhe, Tal. Shahpur, Dist. Thane
A30: ESTIMATE
C36: {{SDE_1}}, | G36: {{SDE_2}}

Sheet Face Sheet
A1: ESTIMATE
A5: Division | B5: : | C5: =CONCATENATE(Cover!B21,Cover!G21) -> {{EE_1}},{{EE_2}}
A7: Sanctioned Estimate No. | B7: : | C7: Vide | D7: for
A9: Capital Head | B9: : | C9: State
A11: Main Head | B11: :
A13: Sub Head | B13: :
A15: Other Head | B15: :
A18: Service Head | B18: :
A20: Divisional Head | B20: :
A22: =CONCATENATE(A23,F23,A24,A25) -> Estimate Prepared in the Office of the Executive Engineer, {{EE_1}},{{EE_2}}For the Probable expenses to be incurred for Preparing Emergency Action Plan of {{Scheme}} {{Type}} and Survey for Computation and defining the Red Line and Blue Line for {{River_Name}} Tal. {{Taluka}}, Dist. {{District}}
A23: Estimate Prepared in the Office of the Executive Engineer, | F23: =C5 -> {{EE_1}},{{EE_2}}
A24: For the Probable expenses to be incurred for
A25: =Cover!A24 -> Preparing Emergency Action Plan of {{Scheme}} {{Type}} and Survey for Computation and defining the Red Line and Blue Line for {{River_Name}} Tal. {{Taluka}}, Dist. {{District}}
A28: Estimated cost Rs. | H28: ='Recapitulation Sheet'!E14 -> #VALUE!
A30: Administratively approved vide No. ----------------------------------- Dated
A31: Technically Sanctioned vide No. ----------------------------------- Dated
A34: Estimate Prepared By Shri
A36: Estimate Checked By Shri
A38: General Description

Sheet Recapitulation Sheet
B2: Name of Work - | D2: =Cover!A24 -> Preparing Emergency Action Plan of {{Scheme}} {{Type}} and Survey for Computation and defining the Red Line and Blue Line for {{River_Name}} Tal. {{Taluka}}, Dist. {{District}}
B3: Recapulation Sheet
C5: Sr. No. | D5: Sub-Estimate | E5: Amount in Rs.
D6: =D2 -> Preparing Emergency Action Plan of {{Scheme}} {{Type}} and Survey for Computation and defining the Red Line and Blue Line for {{River_Name}} Tal. {{Taluka}}, Dist. {{District}}
C7: 1 | D7: ='AB-Jambhe'!C1 -> {{Scheme}} {{Type}} | E7: ='AB-Jambhe'!F44 -> #VALUE!
C9: A | D9: Total Work Cost | E9: =SUM(E7:E8) -> #VALUE!
C10: B | D10: Add 1% Insurance | E10: =ROUND(1%*E9,2) -> #VALUE!
D11: Total | E11: =SUM(E9:E10) -> #VALUE!
C12: C | D12: Add 18 % GST Charges | E12: =ROUND(18%*E9,2) -> #VALUE!
D13: Total | E13: =SUM(E11:E12) -> #VALUE!
D14: Grand Total | E14: =MROUND(E13,1) -> #VALUE!
B16: Prepared by,
B20: A.D.Dubla (J.E).
B21: Junior Engineer | D21: Sub Divisional Engineer | E21: Executive Engineer
D22: =Cover!C36 -> {{SDE_1}}, | E22: =Cover!B21 -> {{EE_1}},
D23: =Cover!G36 -> {{SDE_2}} | E23: =Cover!G21 -> {{EE_2}}
B26: Checked by,

Sheet AB-Jambhe
B1: Name : | C1: {{Scheme}} {{Type}}
A2: =Cover!A23 -> Name of Work - | C2: Preparing Emergency Action Plan of {{Scheme}} {{Type}} and Survey for Computation and defining the Red Line and Blue Line for {{River_Name}} , Tal. {{Taluka}}, Dist. {{District}}
B3: Abstarct
B4: Qty. | C4: Item | D4: Rate | E4: Unit | F4: Amount
C5: Item No.1 :-
B6: ='M-Jambhe'!J13 -> #VALUE! | C6: Cleaning cutting thorny shrubs bushes, grass as directed with 15m lead and lift up to 1.5m. | D6: ='RA '!H11 -> 4.85 | E6: Sq.m | F6: =ROUND(B6*D6,2) -> #VALUE!
C7: Rate Analysis No.1
C8: Item No.2 :-
B9: ='M-Jambhe'!J19 -> 0 | C9: Fixing control points by Differential Global Position System (DGPS) instrument at every One Km. along the both side of river including collection of necessary flood data etc. complete including labour welfare cess, service tax, labour insurance and all applicable taxes etc. complete as directed vide Technical circular of MERI Nashik No.DSO/PB-4/1582 dated 16/11/2015. | D9: ='RA '!H33 -> 1703.7 | E9: Km | F9: =ROUND(B9*D9,2) -> 0
C10: Rate Analysis No.2
C11: Item No.3 :-
B12: ='M-Jambhe'!J28 -> #VALUE! | C12: Traverse Survey along river with cross section at 100 m .c/c along river .The levels on cross section shall be at every 30 m c/c beyond past locally observed flood line, using Differential Global Position System (DGPS) instrument including labor, transportation, using sounding by boat in river water in wet condition and transfer of entire data to computer system in different geo referential layers/ themes using features of standard plotting software computable with design software package including contour plotting at required interval and at a scale and following deliverables etc. all complete as directed vide Technical circular of MERI Nashik No.DSO/PB-4/1582 dated 16/11/2015. | D12: ='RA '!H55 -> 688.65 | E12: Ha. | F12: =ROUND(B12*D12,2) -> #VALUE!
C13: Rate Analysis No.3
C14: Item No.4 :-
B15: ='M-Jambhe'!J32 -> #VALUE! | C15: Delivering Contour map of 0.50 m. contour interval by using standard software & superimposing it on village map with scale1:5000 showing Prohibited line( Blue line) & Restricted line (Red line) along with mapping of structures & other details etc all complete as directed vide Technical circular of MERI Nashik No.DSO/PB-4/1582 dated 16/11/2015. | D15: ='RA '!H76 -> 65.45 | E15: Ha. | F15: =ROUND(B15*D15,2) -> #VALUE!
C16: Rate Analysis No.4
C17: Item No.5 :-
B18: ='M-Jambhe'!J41 -> 2 | C18: Providing computerised detailed cross section drawings in two copies at 100 m interval with actual profile of river (levels at every 30m. distance along cross section) on A-3 size paper with scale 1cm = 15m or 1cm = 30m which is suitable as per site condition showing 25 year return flood line (Blue line) and 100 years return flood line (Red line) computed by software analysis and submission in the form of soft and hard copy as directed by Engineer in charge. So as to use the data of above Item No.BRL01 to BRL03 by HEC-RAS Software. including submission of check print and getting approval of Engineer in charge etc all complete as directed vide Technical circular of MERI Nashik No.DSO/PB-4/1582 dated 16/11/2015. | D18: ='RA '!H96 -> 366.6 | E18: Cross Section | F18: =ROUND(B18*D18,2) -> 733.2
C19: Rate Analysis No.5
C20: Item No.6 :-
B21: ='M-Jambhe'!J45 -> 0 | C21: Computation of Blue line ( 25 Year return flood line ) and red line ( 100 year return flood line ) by using HEC-RAS software including estimation of flood getting approval of competent authority for the same giving all the precise necessary input details into the software, viz. cross sectional and longitudinal features of the stream, flow obstructions etc. including site validation & recalculation to the satisfaction of Engineer In charge etc all complete as directed vide Technical circular of MERI Nashik No.DSO/PB-4/1582 dated 16/11/2015. | D21: ='RA '!H116 -> 3191.1 | E21: Km. | F21: =ROUND(B21*D21,2) -> 0
C22: Rate Analysis No.6
C23: Item No.7 :-
B24: ='M-Jambhe'!J51 -> 0 | C24: Providing computerised detailed river alignment with contours on A-1 size paper with scale 1 cm equal to 15 m or 30m whichever is suitable as per site condition. (one sheet for one Km. length of river) with contour at 0.50 m. interval including marking 25 years return flood level (Blue line) & 100 years return flood level (Red line) line & showing locations of bridges, KT Weirs & other permanent structures on each drawing along and across the river as directed by Engineer in Charge, including providing one color check print & six hard copies(color print) with one soft copy etc. all complete as directed vide Technical circular of MERI Nashik No.DSO/PB-4/1582 dated 16/11/2015. | D24: ='RA '!H132 -> 2005.45 | E24: Sheet | F24: =ROUND(B24*D24,2) -> 0
C25: Rate Analysis No.7
C26: Item No.8 :-
B27: ='M-Jambhe'!J60 -> 2 | C27: Marking of 25 years flood level ( blue line) & 100 years flood level ( Red line) on permanent structures like Bridges, Temples & other permanent structures along & across river including painting, lettering at every not less than 100 m. interval & not more than 500 m. on both the banks of river, after the final approval of flood level. as directed by engineer in charge etc. all complete as directed vide Technical circular of MERI Nashik No.DSO/PB-4/1582 dated 16/11/2015. | D27: ='RA '!H153 -> 701.1 | E27: No. | F27: =ROUND(B27*D27,2) -> 1402.2
C28: Rate Analysis No.8
C29: Item No.9 :-
B30: ='M-Jambhe'!J70 -> #VALUE! | C30: Conducting Bathymetric Survey along the river/canal/stream using Echo Sounder and Differential GPS/RTK for depth measurement and position fixing, including mobilization of survey boat with operator, equipment calibration, data acquisition, processing, preparation of longitudinal and cross-sections, contour maps, and submission of reports complete as directed. | D30: ='RA '!H170 -> 400000 | E30: Sq.km | F30: =ROUND(B30*D30,2) -> #VALUE!
C31: Rate Analysis No.9
C32: Item No.10 :-
B33: ='M-Jambhe'!J82 -> #VALUE! | C33: To carry out Aerial LIDAR and Aerial Imagery survey with Aircraft/ Helicopter using Aerial LIDAR scanner integrated with Aerial Camera of not less than 100 MP resolution including establishment of ground control points at 2km grid using survey grade dual frequency DGPS-PPK system and post processing the data. The aerial LIDAR data should satisfy point density of 10 points per sq.m, fundamental horizontal accuracy of 15 cm, fundamental vertical accuracy of 15 cm and ground sampling distance (GSD) of 10 cm.1. Geotagged images in JPG format with GSD < 5 cm2. GCP values in .CSV format. 3. 3D point cloud cover in .las format4. Digital surface model (DSM) and Digital Elevation Model (DEM) in .tiff format. with 5 cm resolution which gives capability to capture detailed features And all the allied data required as directed by Engineer-in-charge as per the specifications etc. complete. | D33: ='RA '!H189 -> 48600 | E33: Sq.km | F33: =ROUND(B33*D33,2) -> #VALUE! | L33: 400
C34: Rate Analysis No.10
C35: Item No.11 :-
B36: 1 | C36: Preparation of Emergency Action Plan which includes | D36: {{Rate}} | E36: Job | F36: =ROUND(B36*D36,2) -> #VALUE!
C37: i) Collection of DEM for the probable inundation area from reliable sources and conducting Dam break analysis
C38: ii) Collecting required Data from I.M.D. and Revenue including necessary fees
C39: iii) Preparation of inundation mapping as per CWC guidelines with HecRas or similar software with planning of escape routes for all important inundation places.
C40: iv) Preparing detailed EAP report as per templates given in guidelines of CWC manual.
...

Sheet M-Jambhe
B1: ='AB-Jambhe'!A2 -> Name of Work - | C1: ='AB-Jambhe'!C2 -> Preparing Emergency Action Plan of {{Scheme}} {{Type}} and Survey for Computation and defining the Red Line and Blue Line for {{River_Name}} , Tal. {{Taluka}}, Dist. {{District}}
B2: Measurement Sheet | M2: Length of The River | O2: 15 | P2: Km
B3: ='AB-Jambhe'!C5 -> Item No.1 :- | C3: ='AB-Jambhe'!C6 -> Cleaning cutting thorny shrubs bushes, grass as directed with 15m lead and lift up to 1.5m. | M3: Width of Survey | O3: 350 | P3: m
C4: Total Length of River from D/s of Dam to {{Confluence}}Confluence | H4: = | I4: {{Length}} | J4: Km | M4: Width of River | O4: 25 | P4: m
M5: Area of Submergence | O5: 1.032 | P5: m
D6: Total Length | I6: =SUM(I4:I5) -> 0 | J6: Km | M6: River Length for bathyematric | O6: 12 | P6: m
C8: Width one side of river | H8: = | I8: {{One_Side}} | J8: m
C9: For Both Side of river | H9: = | I9: =I8*2 -> #VALUE! | J9: m
C11: Total area of Grid survey | H11: = | I11: =I9*(I6*1000) -> #VALUE! | J11: Sq.m
C13: Area of cleaning ( 1.0% of Total Area ) = | J13: =ROUND(I11*1%,0) -> #VALUE! | K13: Sqm.
B15: ='AB-Jambhe'!C8 -> Item No.2 :- | C15: ='AB-Jambhe'!C9 -> Fixing control points by Differential Global Position System (DGPS) instrument at every One Km. along the both side of river including collection of necessary flood data etc. complete including labour welfare cess, service tax, labour insurance and all applicable taxes etc. complete as directed vide Technical circular of MERI Nashik No.DSO/PB-4/1582 dated 16/11/2015.
C16: Total Length of River | H16: = | I16: =I4 -> {{Length}} | J16: Km
D17: Total Length | I17: =SUM(I16:I16) -> 0 | J17: Km
D19: No. of points Say | E19: = | F19: =I17 -> 0 | G19: say~ | H19: =ROUNDUP(F19,0) -> 0 | I19: x 2 = | J19: =ROUND(I17,0)*2 -> 0 | K19: Km
B21: ='AB-Jambhe'!C11 -> Item No.3 :- | C21: ='AB-Jambhe'!C12 -> Traverse Survey along river with cross section at 100 m .c/c along river .The levels on cross section shall be at every 30 m c/c beyond past locally observed flood line, using Differential Global Position System (DGPS) instrument including labor, transportation, using sounding by boat in river water in wet condition and transfer of entire data to computer system in different geo referential layers/ themes using features of standard plotting software computable with design software package including contour plotting at required interval and at a scale and following deliverables etc. all complete as directed vide Technical circular of MERI Nashik No.DSO/PB-4/1582 dated 16/11/2015.
C22: Total Length River & Nala = | H22: = | I22: =I16 -> {{Length}} | J22: Km
D23: Total Length | I23: =SUM(I22:I22) -> 0 | J23: Km
C24: Width of strip for Grid Survey along River | H24: = | I24: =C25*2 -> #VALUE! | J24: Km
C25: {{Strip_Width}} | D25: m on either side
C26: Grid survey | F26: =I23*1000 -> 0 | G26: x | H26: =I24 -> #VALUE! | I26: = | J26: =F26*H26/F27 -> #VALUE!
F27: 10000
C28: Hence, | D28: Total Grid/Contour survey = | J28: =J26 -> #VALUE! | K28: Ha.
B30: ='AB-Jambhe'!C14 -> Item No.4 :- | C30: ='AB-Jambhe'!C15 -> Delivering Contour map of 0.50 m. contour interval by using standard software & superimposing it on village map with scale1:5000 showing Prohibited line( Blue line) & Restricted line (Red line) along with mapping of structures & other details etc all complete as directed vide Technical circular of MERI Nashik No.DSO/PB-4/1582 dated 16/11/2015.
D32: Total Area as per Item No.3 | H32: = | J32: =J28 -> #VALUE! | K32: =K28 -> Ha.
B35: ='AB-Jambhe'!C17 -> Item No.5 :- | C35: ='AB-Jambhe'!C18 -> Providing computerised detailed cross section drawings in two copies at 100 m interval with actual profile of river (levels at every 30m. distance along cross section) on A-3 size paper with scale 1cm = 15m or 1cm = 30m which is suitable as per site condition showing 25 year return flood line (Blue line) and 100 years return flood line (Red line) computed by software analysis and submission in the form of soft and hard copy as directed by Engineer in charge. So as to use the data of above Item No.BRL01 to BRL03 by HEC-RAS Software. including submission of check print and getting approval of Engineer in charge etc all complete as directed vide Technical circular of MERI Nashik No.DSO/PB-4/1582 dated 16/11/2015.
C36: Total Length River | H36: = | I36: =I22 -> {{Length}} | J36: Km
D37: Total Length | I37: =SUM(I36:I36) -> 0 | J37: Km
C38: Each cross section at 100 m interval
C39: No. of cross sections = | F39: =ROUNDUP(I37/0.1,0)+1 -> 1 | G39: No.s
C40: No. of cross sections for two sets = | F40: =F39*2 -> 2 | G40: =G39 -> No.s
C41: Hence, | D41: No. of sheets | J41: =F40 -> 2 | K41: C/s
B43: ='AB-Jambhe'!C20 -> Item No.6 :- | C43: ='AB-Jambhe'!C21 -> Computation of Blue line ( 25 Year return flood line ) and red line ( 100 year return flood line ) by using HEC-RAS software including estimation of flood getting approval of competent authority for the same giving all the precise necessary input details into the software, viz. cross sectional and longitudinal features of the stream, flow obstructions etc. including site validation & recalculation to the satisfaction of Engineer In charge etc all complete as directed vide Technical circular of MERI Nashik No.DSO/PB-4/1582 dated 16/11/2015.
C45: Total Qty as Item. No.2 above = | J45: =I17 -> 0 | K45: Km
B48: ='AB-Jambhe'!C23 -> Item No.7 :- | C48: ='AB-Jambhe'!C24 -> Providing computerised detailed river alignment with contours on A-1 size paper with scale 1 cm equal to 15 m or 30m whichever is suitable as per site condition. (one sheet for one Km. length of river) with contour at 0.50 m. interval including marking 25 years return flood level (Blue line) & 100 years return flood level (Red line) line & showing locations of bridges, KT Weirs & other permanent structures on each drawing along and across the river as directed by Engineer in Charge, including providing one color check print & six hard copies(color print) with one soft copy etc. all complete as directed vide Technical circular of MERI Nashik No.DSO/PB-4/1582 dated 16/11/2015.
C50: One sheet for one Km. length of river
F51: =J45 -> 0 | G51: = | H51: =F51/1 -> 0 | I51: Says | J51: =ROUNDUP(H51,0) -> 0 | K51: Sheets
F52: 1
B54: ='AB-Jambhe'!C26 -> Item No.8 :- | C54: ='AB-Jambhe'!C27 -> Marking of 25 years flood level ( blue line) & 100 years flood level ( Red line) on permanent structures like Bridges, Temples & other permanent structures along & across river including painting, lettering at every not less than 100 m. interval & not more than 500 m. on both the banks of river, after the final approval of flood level. as directed by engineer in charge etc. all complete as directed vide Technical circular of MERI Nashik No.DSO/PB-4/1582 dated 16/11/2015.
C55: Total Length River | H55: = | I55: =I36 -> {{Length}} | J55: Km
D56: Total Length | I56: =SUM(I55:I55) -> 0 | J56: Km
...

Sheet RA 
B1: Name of Work :- | C1: ='M-Jambhe'!C1 -> Preparing Emergency Action Plan of {{Scheme}} {{Type}} and Survey for Computation and defining the Red Line and Blue Line for {{River_Name}} , Tal. {{Taluka}}, Dist. {{District}}
B2: Rate Analysis
B3: ='AB-Jambhe'!C5 -> Item No.1 :- | C3: ='AB-Jambhe'!C6 -> Cleaning cutting thorny shrubs bushes, grass as directed with 15m lead and lift up to 1.5m.
C4: Basic Rate as per
C5: CSR 2023-24, Pg. No. 64 / I. No.-MR-4 | G5: Rs. | H5: 4.35 | I5: /Sqm.
C6: Add 10 % for Triabal area | G6: Rs. | H6: =ROUND(H5*0.1,2) -> 0.44 | I6: =I5 -> /Sqm.
F7: Total | G7: Rs. | H7: =SUM(H5:H6) -> 4.79 | I7: =I6 -> /Sqm.
C8: Add 1% for Labour Welfare Cess | G8: Rs. | H8: =ROUND(H5*0.01,2) -> 0.04 | I8: =I7 -> /Sqm.
F9: Grand total | G9: Rs. | H9: =SUM(H7:H8) -> 4.83 | I9: =I8 -> /Sqm.
F11: Say | G11: Rs. | H11: =MROUND(H9,0.05) -> 4.85 | I11: =I9 -> /Sqm.
B12: Prepared by
B17: ='Recapitulation Sheet'!$B$21 -> Junior Engineer | E17: ='Recapitulation Sheet'!$D$21 -> Sub Divisional Engineer | H17: ='Recapitulation Sheet'!$E$21 -> Executive Engineer
E18: ='Recapitulation Sheet'!$D$22 -> {{SDE_1}}, | H18: ='Recapitulation Sheet'!$E$22 -> {{EE_1}},
E19: ='Recapitulation Sheet'!$D$23 -> {{SDE_2}} | H19: ='Recapitulation Sheet'!$E$23 -> {{EE_2}}
B21: Checked by
B25: ='AB-Jambhe'!C8 -> Item No.2 :- | C25: ='AB-Jambhe'!C9 -> Fixing control points by Differential Global Position System (DGPS) instrument at every One Km. along the both side of river including collection of necessary flood data etc. complete including labour welfare cess, service tax, labour insurance and all applicable taxes etc. complete as directed vide Technical circular of MERI Nashik No.DSO/PB-4/1582 dated 16/11/2015.
C26: Basic Rate as per
C27: CSR 2023-24, Pg. No.59 / I. No.-BRL-01 | G27: Rs. | H27: 1534.85 | I27: /km.
C28: Add 10 % for Triabal area | G28: Rs. | H28: =ROUND(H27*0.1,2) -> 153.49 | I28: =I27 -> /km.
F29: Total | G29: Rs. | H29: =SUM(H27:H28) -> 1688.34 | I29: =I27 -> /km.
C30: Add 1% for Labour Welfare Cess | G30: Rs. | H30: =H27*1% -> 15.3485 | I30: =I27 -> /km.
F31: Grand total | G31: Rs. | H31: =SUM(H29:H30) -> 1703.6885 | I31: =I30 -> /km.
F33: Say | G33: Rs. | H33: =MROUND(H31,0.05) -> 1703.7 | I33: =I27 -> /km.
B34: Prepared by
B39: ='Recapitulation Sheet'!$B$21 -> Junior Engineer | E39: ='Recapitulation Sheet'!$D$21 -> Sub Divisional Engineer | H39: ='Recapitulation Sheet'!$E$21 -> Executive Engineer
E40: ='Recapitulation Sheet'!$D$22 -> {{SDE_1}}, | H40: ='Recapitulation Sheet'!$E$22 -> {{EE_1}},
E41: ='Recapitulation Sheet'!$D$23 -> {{SDE_2}} | H41: ='Recapitulation Sheet'!$E$23 -> {{EE_2}}
B43: Checked by
B46: ='AB-Jambhe'!C11 -> Item No.3 :- | C46: ='AB-Jambhe'!C12 -> Traverse Survey along river with cross section at 100 m .c/c along river .The levels on cross section shall be at every 30 m c/c beyond past locally observed flood line, using Differential Global Position System (DGPS) instrument including labor, transportation, using sounding by boat in river water in wet condition and transfer of entire data to computer system in different geo referential layers/ themes using features of standard plotting software computable with design software package including contour plotting at required interval and at a scale and following deliverables etc. all complete as directed vide Technical circular of MERI Nashik No.DSO/PB-4/1582 dated 16/11/2015.
C47: A) Dry
C48: Basic Rate
C49: CSR 2023-24, Pg. No.59 / I. No.-BRL-02 a | G49: Rs. | H49: 620.4 | I49: /Ha.
C50: Add 10 % for Triabal area | G50: Rs. | H50: =ROUND(H49*0.1,2) -> 62.04 | I50: =I49 -> /Ha.
F51: Total | G51: Rs. | H51: =SUM(H49:H50) -> 682.44 | I51: =I49 -> /Ha.
C52: Add 1% for Labour Welfare Cess | G52: Rs. | H52: =ROUND(H49*0.01,2) -> 6.2 | I52: =I49 -> /Ha.
F53: Grand total | G53: Rs. | H53: =SUM(H51:H52) -> 688.64 | I53: =I52 -> /Ha.
F55: Say | G55: Rs. | H55: =MROUND(H53,0.05) -> 688.65 | I55: =I49 -> /Ha.
B56: Prepared by
B61: ='Recapitulation Sheet'!$B$21 -> Junior Engineer | E61: ='Recapitulation Sheet'!$D$21 -> Sub Divisional Engineer | H61: ='Recapitulation Sheet'!$E$21 -> Executive Engineer
E62: ='Recapitulation Sheet'!$D$22 -> {{SDE_1}}, | H62: ='Recapitulation Sheet'!$E$22 -> {{EE_1}},
...
